Workbook

Sheet Summary
B3: Risk Level | C3: Macro Index | D3: NVT Combi | E3: MVRV | F3: NUPL | G3: STH Supply | H3: RHODL ratio | I3: VDD Multiple | J3: M2 YoY Change | K3: Cycle Capital Flows | L3: Fear & Greed | M3: Total Strategy 1
A4: Start | B4: ='Risk Level'!$B53 -> 42005 | C4: ='Macro Index'!$B53 -> 42005 | D4: ='NVT Combi'!$B53 -> 42005 | E4: =MVRV!$B53 -> 42005 | F4: =NUPL!$B53 -> 42005 | G4: ='STH Supply'!$B53 -> 42005 | H4: ='RHODL Ratio'!$B53 -> 42005 | I4: ='VDD Multiple'!$B53 -> 42005 | J4: ='M2 Yoy Change'!$B53 -> 42005 | K4: ='Cycle Capital Flows'!$B53 -> 42005 | L4: ='Fear Greed'!$B53 -> 42005 | M4: ='TS1'!$B53 -> 42005
A5: End | B5: ='Risk Level'!$B54 -> 45629 | C5: ='Macro Index'!$B54 -> 45629 | D5: ='NVT Combi'!$B54 -> 45629 | E5: =MVRV!$B54 -> 45629 | F5: =NUPL!$B54 -> 45629 | G5: ='STH Supply'!$B54 -> 45629 | H5: ='RHODL Ratio'!$B54 -> 45629 | I5: ='VDD Multiple'!$B54 -> 45629 | J5: ='M2 Yoy Change'!$B54 -> 45629 | K5: ='Cycle Capital Flows'!$B54 -> 45629 | L5: ='Fear Greed'!$B54 -> 45629 | M5: ='TS1'!$B54 -> 45629
A6: Duration | B6: ='Risk Level'!$B55 -> 3624 days 00:00:00 | C6: ='Macro Index'!$B55 -> 3624 days 00:00:00 | D6: ='NVT Combi'!$B55 -> 3624 days 00:00:00 | E6: =MVRV!$B55 -> 3624 days 00:00:00 | F6: =NUPL!$B55 -> 3624 days 00:00:00 | G6: ='STH Supply'!$B55 -> 3624 days 00:00:00 | H6: ='RHODL Ratio'!$B55 -> 3624 days 00:00:00 | I6: ='VDD Multiple'!$B55 -> 3624 days 00:00:00 | J6: ='M2 Yoy Change'!$B55 -> 3624 days 00:00:00 | K6: ='Cycle Capital Flows'!$B55 -> 3624 days 00:00:00 | L6: ='Fear Greed'!$B55 -> 3624 days 00:00:00 | M6: ='TS1'!$B55 -> 3624 days 00:00:00
A7: Exposure Time [%] | B7: ='Risk Level'!$B56 -> 84.303448 | C7: ='Macro Index'!$B56 -> 60.082759 | D7: ='NVT Combi'!$B56 -> 74.344828 | E7: =MVRV!$B56 -> 83.917241 | F7: =NUPL!$B56 -> 78.068966 | G7: ='STH Supply'!$B56 -> 80.689655 | H7: ='RHODL Ratio'!$B56 -> 72.413793 | I7: ='VDD Multiple'!$B56 -> 85.931034 | J7: ='M2 Yoy Change'!$B56 -> 46.068966 | K7: ='Cycle Capital Flows'!$B56 -> 72.248276 | L7: ='Fear Greed'!$B56 -> 67.062069 | M7: ='TS1'!$B56 -> 83.889655
A8: Equity Final [$] | B8: ='Risk Level'!$B57 -> 2287746.2 | C8: ='Macro Index'!$B57 -> 1476236.1 | D8: ='NVT Combi'!$B57 -> 1741386.6 | E8: =MVRV!$B57 -> 7703642.4 | F8: =NUPL!$B57 -> 80833.742 | G8: ='STH Supply'!$B57 -> 6600176.6 | H8: ='RHODL Ratio'!$B57 -> 1179793.1 | I8: ='VDD Multiple'!$B57 -> 1665190.4 | J8: ='M2 Yoy Change'!$B57 -> 138703.12 | K8: ='Cycle Capital Flows'!$B57 -> 109838.15 | L8: ='Fear Greed'!$B57 -> 858679.82 | M8: ='TS1'!$B57 -> 8979372.5
A9: Equity Peak [$] | B9: ='Risk Level'!$B58 -> 2500111.2 | C9: ='Macro Index'!$B58 -> 1514657.8 | D9: ='NVT Combi'!$B58 -> 1903036.3 | E9: =MVRV!$B58 -> 7950388.9 | F9: =NUPL!$B58 -> 194757.09 | G9: ='STH Supply'!$B58 -> 6811725.7 | H9: ='RHODL Ratio'!$B58 -> 1217719.4 | I9: ='VDD Multiple'!$B58 -> 2231700.8 | J9: ='M2 Yoy Change'!$B58 -> 161661.08 | K9: ='Cycle Capital Flows'!$B58 -> 110155.35 | L9: ='Fear Greed'!$B58 -> 921091.59 | M9: ='TS1'!$B58 -> 9244432.4
A10: Return [%] | B10: ='Risk Level'!$B59 -> 22777.462 | C10: ='Macro Index'!$B59 -> 14662.361 | D10: ='NVT Combi'!$B59 -> 17313.866 | E10: =MVRV!$B59 -> 76936.424 | F10: =NUPL!$B59 -> 708.33742 | G10: ='STH Supply'!$B59 -> 65901.766 | H10: ='RHODL Ratio'!$B59 -> 11697.931 | I10: ='VDD Multiple'!$B59 -> 16551.904 | J10: ='M2 Yoy Change'!$B59 -> 1287.0312 | K10: ='Cycle Capital Flows'!$B59 -> 998.38147 | L10: ='Fear Greed'!$B59 -> 8486.7982 | M10: ='TS1'!$B59 -> 89693.725
A11: Buy & Hold Return [%] | B11: ='Risk Level'!$B60 -> 30344.78 | C11: ='Macro Index'!$B60 -> 30344.78 | D11: ='NVT Combi'!$B60 -> 30344.78 | E11: =MVRV!$B60 -> 30344.78 | F11: =NUPL!$B60 -> 30344.78 | G11: ='STH Supply'!$B60 -> 30344.78 | H11: ='RHODL Ratio'!$B60 -> 30344.78 | I11: ='VDD Multiple'!$B60 -> 30344.78 | J11: ='M2 Yoy Change'!$B60 -> 30344.78 | K11: ='Cycle Capital Flows'!$B60 -> 30344.78 | L11: ='Fear Greed'!$B60 -> 30344.78 | M11: ='TS1'!$B60 -> 30344.78
A12: Return (Ann.) [%] | B12: ='Risk Level'!$B61 -> 72.809639 | C12: ='Macro Index'!$B61 -> 65.352799 | D12: ='NVT Combi'!$B61 -> 68.126032 | E12: =MVRV!$B61 -> 95.281201 | F12: =NUPL!$B61 -> 23.419901 | G12: ='STH Supply'!$B61 -> 92.264931 | H12: ='RHODL Ratio'!$B61 -> 61.662547 | I12: ='VDD Multiple'!$B61 -> 67.370315 | J12: ='M2 Yoy Change'!$B61 -> 30.315559 | K12: ='Cycle Capital Flows'!$B61 -> 27.289647 | L12: ='Fear Greed'!$B61 -> 56.572975 | M12: ='TS1'!$B61 -> 98.317628
A13: Volatility (Ann.) [%] | B13: ='Risk Level'!$B62 -> 91.269725 | C13: ='Macro Index'!$B62 -> 72.312707 | D13: ='NVT Combi'!$B62 -> 90.006043 | E13: =MVRV!$B62 -> 112.01693 | F13: =NUPL!$B62 -> 61.221092 | G13: ='STH Supply'!$B62 -> 107.31324 | H13: ='RHODL Ratio'!$B62 -> 83.504602 | I13: ='VDD Multiple'!$B62 -> 91.439618 | J13: ='M2 Yoy Change'!$B62 -> 46.580385 | K13: ='Cycle Capital Flows'!$B62 -> 61.208412 | L13: ='Fear Greed'!$B62 -> 64.514586 | M13: ='TS1'!$B62 -> 108.467
A14: Sharpe Ratio | B14: ='Risk Level'!$B63 -> 0.79774141 | C14: ='Macro Index'!$B63 -> 0.90375263 | D14: ='NVT Combi'!$B63 -> 0.75690509 | E14: =MVRV!$B63 -> 0.85059644 | F14: =NUPL!$B63 -> 0.38254628 | G14: ='STH Supply'!$B63 -> 0.85977214 | H14: ='RHODL Ratio'!$B63 -> 0.73843293 | I14: ='VDD Multiple'!$B63 -> 0.73677381 | J14: ='M2 Yoy Change'!$B63 -> 0.65082242 | K14: ='Cycle Capital Flows'!$B63 -> 0.44584798 | L14: ='Fear Greed'!$B63 -> 0.87690208 | M14: ='TS1'!$B63 -> 0.90642892
A15: Sortino Ratio | B15: ='Risk Level'!$B64 -> 2.1966336 | C15: ='Macro Index'!$B64 -> 2.4173377 | D15: ='NVT Combi'!$B64 -> 2.0563923 | E15: =MVRV!$B64 -> 2.7201551 | F15: =NUPL!$B64 -> 0.73980718 | G15: ='STH Supply'!$B64 -> 2.7639631 | H15: ='RHODL Ratio'!$B64 -> 1.9323076 | I15: ='VDD Multiple'!$B64 -> 1.924942 | J15: ='M2 Yoy Change'!$B64 -> 1.3324466 | K15: ='Cycle Capital Flows'!$B64 -> 0.86612968 | L15: ='Fear Greed'!$B64 -> 2.2108072 | M15: ='TS1'!$B64 -> 3.0263918
... A30: SQN | B30: ='Risk Level'!$B79 -> 2.8352954 | C30: ='Macro Index'!$B79 -> 2.4664014 | D30: ='NVT Combi'!$B79 -> 2.4862077 | E30: =MVRV!$B79 -> 2.0861977 | F30: =NUPL!$B79 -> 0.66079757 | G30: ='STH Supply'!$B79 -> 1.5964873 | H30: ='RHODL Ratio'!$B79 -> 1.1253649 | I30: ='VDD Multiple'!$B79 -> 0.96664349 | J30: ='M2 Yoy Change'!$B79 -> 1.8597273 | K30: ='Cycle Capital Flows'!$B79 -> 1.6085998 | L30: ='Fear Greed'!$B79 -> 2.5601787 | M30: ='TS1'!$B79 -> 1.422994
B34: Total Strategy 0 | C34: Total Strategy 1 | D34: Total Strategy 2 | E34: Total Strategy 3 | F34: Total Strategy 4 | G34: Total Strat. 4 - 2017 | H34: Total Strat. 4 - 2018 | I34: Total Strat. 4 - 2013 | J34: Total Strategy 8 | K34: Total Strategy 9 | L34: Total Strategy 10 | M34: Total Strategy 11
A35: Start | B35: =TS0!$B53 -> 42005 | C35: ='TS1'!$B53 -> 42005 | D35: ='TS2'!$B53 -> 42005 | E35: ='TS3'!$B53 -> 42005 | F35: ='TS4'!$B53 -> 42005 | G35: ='TS4'!$E53 -> 42736 | H35: ='TS4'!$H53 -> 43101 | I35: ='TS4'!$K53 -> 41275
A36: End | B36: =TS0!$B54 -> 45629 | C36: ='TS1'!$B54 -> 45629 | D36: ='TS2'!$B54 -> 45629 | E36: ='TS3'!$B54 -> 45629 | F36: ='TS4'!$B54 -> 45629 | G36: ='TS4'!$E54 -> 45629 | H36: ='TS4'!$H54 -> 45629 | I36: ='TS4'!$K54 -> 45629
A37: Duration | B37: =TS0!$B55 -> 3624 days 00:00:00 | C37: ='TS1'!$B55 -> 3624 days 00:00:00 | D37: ='TS2'!$B55 -> 3624 days 00:00:00 | E37: ='TS3'!$B55 -> 3624 days 00:00:00 | F37: ='TS4'!$B55 -> 3624 days 00:00:00 | G37: ='TS4'!$E55 -> 2893 days 00:00:00 | H37: ='TS4'!$H55 -> 2528 days 00:00:00 | I37: ='TS4'!$K55 -> 4354 days 00:00:00
A38: Exposure Time [%] | B38: =TS0!$B56 -> 95.889655 | C38: ='TS1'!$B56 -> 83.889655 | D38: ='TS2'!$B56 -> 95.889655 | E38: ='TS3'!$B56 -> 99.42069 | F38: ='TS4'!$B56 -> 94.593103 | G38: ='TS4'!$E56 -> 75.224603 | H38: ='TS4'!$H56 -> 97.864769 | I38: ='TS4'!$K56 -> 93.226177
A39: Equity Final [$] | B39: =TS0!$B57 -> 1.0718427e+08 | C39: ='TS1'!$B57 -> 8979372.5 | D39: ='TS2'!$B57 -> 43770150 | E39: ='TS3'!$B57 -> 99410880 | F39: ='TS4'!$B57 -> 1.4296652e+08 | G39: ='TS4'!$E57 -> 1217758.8 | H39: ='TS4'!$H57 -> 1225244.9 | I39: ='TS4'!$K57 -> 1207580148
A40: Equity Peak [$] | B40: =TS0!$B58 -> 1.099378e+08 | C40: ='TS1'!$B58 -> 9244432.4 | D40: ='TS2'!$B58 -> 44894590 | E40: ='TS3'!$B58 -> 102000428 | F40: ='TS4'!$B58 -> 1.4663929e+08 | G40: ='TS4'!$E58 -> 1249042.2 | H40: ='TS4'!$H58 -> 1256720.1 | I40: ='TS4'!$K58 -> 1239036346
A41: Return [%] | B41: =TS0!$B59 -> 1071742.7 | C41: ='TS1'!$B59 -> 89693.725 | D41: ='TS2'!$B59 -> 437601.5 | E41: ='TS3'!$B59 -> 994008.8 | F41: ='TS4'!$B59 -> 1429565.2 | G41: ='TS4'!$E59 -> 12077.588 | H41: ='TS4'!$H59 -> 12152.449 | I41: ='TS4'!$K59 -> 12075701
A42: Buy & Hold Return [%] | B42: =TS0!$B60 -> 30344.78 | C42: ='TS1'!$B60 -> 30344.78 | D42: ='TS2'!$B60 -> 30344.78 | E42: ='TS3'!$B60 -> 30344.78 | F42: ='TS4'!$B60 -> 30344.78 | G42: ='TS4'!$E60 -> 9509.6554 | H42: ='TS4'!$H60 -> 611.73761 | I42: ='TS4'!$K60 -> 718753.3
A43: Return (Ann.) [%] | B43: =TS0!$B61 -> 154.56137 | C43: ='TS1'!$B61 -> 98.317628 | D43: ='TS2'!$B61 -> 132.61031 | E43: ='TS3'!$B61 -> 152.63891 | F43: ='TS4'!$B61 -> 162.05299 | G43: ='TS4'!$E61 -> 83.247168 | H43: ='TS4'!$H61 -> 100.16331 | I43: ='TS4'!$K61 -> 166.63924
A44: Volatility (Ann.) [%] | B44: =TS0!$B62 -> 142.16007 | C44: ='TS1'!$B62 -> 108.467 | D44: ='TS2'!$B62 -> 118.44699 | E44: ='TS3'!$B62 -> 128.57773 | F44: ='TS4'!$B62 -> 162.66957 | G44: ='TS4'!$E62 -> 92.131552 | H44: ='TS4'!$H62 -> 119.31467 | I44: ='TS4'!$K62 -> 152.58025
A45: Sharpe Ratio | B45: =TS0!$B63 -> 1.0872348 | C45: ='TS1'!$B63 -> 0.90642892 | D45: ='TS2'!$B63 -> 1.1195751 | E45: ='TS3'!$B63 -> 1.1871333 | F45: ='TS4'!$B63 -> 0.99620962 | G45: ='TS4'!$E63 -> 0.9035685 | H45: ='TS4'!$H63 -> 0.83948866 | I45: ='TS4'!$K63 -> 1.0921417
A46: Sortino Ratio | B46: =TS0!$B64 -> 4.58438 | C46: ='TS1'!$B64 -> 3.0263918 | D46: ='TS2'!$B64 -> 4.2492716 | E46: ='TS3'!$B64 -> 5.0554565 | F46: ='TS4'!$B64 -> 4.4490227 | G46: ='TS4'!$E64 -> 2.6825126 | H46: ='TS4'!$H64 -> 2.7512591 | I46: ='TS4'!$K64 -> 5.1679105
... A61: SQN | B61: =TS0!$B79 -> 2.8378271 | C61: ='TS1'!$B79 -> 1.422994 | D61: ='TS2'!$B79 -> 2.8852914 | E61: ='TS3'!$B79 -> 2.3607549 | F61: ='TS4'!$B79 -> 2.3067261 | G61: ='TS4'!$E79 -> 2.2525062 | H61: ='TS4'!$H79 -> 2.3421952 | I61: ='TS4'!$K79 -> 2.394498

Sheet TS0
A1: Total Strategy 0 - original
A3: Risk Level | B3: Macro Index | C3: NVT Combi | D3: MVRV | E3: NUPL | F3: STH Supply | G3: RHODL ratio | H3: VDD Multiple | I3: M2 YoY Change | J3: Cycle Capital Flows | K3: Fear & Greed
A4: x | B4: x | C4: x | E4: x | G4: x | H4: x
A53: Start | B53: 42005
A54: End | B54: 45629
A55: Duration | B55: 3624 days 00:00:00
A56: Exposure Time [%] | B56: 95.889655
A57: Equity Final [$] | B57: 1.0718427e+08
A58: Equity Peak [$] | B58: 1.099378e+08
A59: Return [%] | B59: 1071742.7
A60: Buy & Hold Return [%] | B60: 30344.78
A61: Return (Ann.) [%] | B61: 154.56137
A62: Volatility (Ann.) [%] | B62: 142.16007
A63: Sharpe Ratio | B63: 1.0872348
A64: Sortino Ratio | B64: 4.58438
A65: Calmar Ratio | B65: 2.8840639
A66: Max. Drawdown [%] | B66: -53.591523
A67: Avg. Drawdown [%] | B67: -6.0256301
A68: Max. Drawdown Duration | B68: 596 days 00:00:00
A69: Avg. Drawdown Duration | B69: 18 days 00:00:00
A70: # Trades | B70: 27
A71: Win Rate [%] | B71: 96.296296
A72: Best Trade [%] | B72: 1036.2076
A73: Worst Trade [%] | B73: -2.2823245
A74: Avg. Trade [%] | B74: 107.26926
A75: Max. Trade Duration | B75: 753 days 00:00:00
A76: Avg. Trade Duration | B76: 227 days 00:00:00
A77: Profit Factor | B77: 2142.7598
A78: Expectancy [%] | B78: 181.0441
A79: SQN | B79: 2.8378271
A80: _strategy | B80: Matrix
A81: _equity_curve | B81: Equity DrawdownPct DrawdownDuration time 2015-01-01 1.000000e+04 0.000000 NaT 2015-01-02 1.000000e+04 0.000000 NaT 2015-01-03 1.000000e+04 0.000000 NaT 2015-01-04 1.000000e+04 0.000000 NaT 2015-01-05 1.000000e+04 0.000000 NaT ... ... ... ... 2024-11-29 1.086260e+08 0.011932 NaT 2024-11-30 1.077894e+08 0.019542 NaT 2024-12-01 1.085005e+08 0.013074 NaT 2024-12-02 1.071843e+08 0.025046 NaT 2024-12-03 1.071843e+08 0.025046 11 days [3625 rows x 3 columns]
A82: _trades | B82: Size EntryBar ExitBar EntryPrice ExitPrice PnL ReturnPct EntryTime ExitTime Duration Size_adapted EntryPrice_adapted ExitPrice_adapted 0 54 819 902 1.038507 2.639261 8.644074e+01 1.541400 2017-03-30 2017-06-21 83 days 0.054 1038.506694 2639.2612 1 306 648 902 0.618394 2.639261 6.183853e+02 3.267927 2016-10-10 2017-06-21 254 days 0.306 618.394243 2639.2612 2 1530 432 902 0.411632 2.639261 3.408273e+03 5.411706 2016-03-08 2017-06-21 470 days 1.530 411.631673 2639.2612 3 9040 239 902 0.232287 2.639261 2.175905e+04 10.362076 2015-08-28 2017-06-21 663 days 9.040 232.286885 2639.2612 4 30055 149 902 0.232905 2.639261 7.232303e+04 10.331914 2015-05-30 2017-06-21 753 days 30.055 232.905164 2639.2612 5 -28710 902 937 2.637942 2.522325 3.319360e+03 0.043828 2017-06-21 2017-07-26 35 days -28.710 2637.941569 2522.3247 6 30932 937 968 2.523586 4.341978 5.624652e+04 0.720559 2017-07-26 2017-08-26 31 days 30.932 2523.585862 4341.9785 7 -27059 968 1010 4.339808 4.438856 -2.680153e+03 -0.022823 2017-08-26 2017-10-07 42 days -27.059 4339.807511 4438.8560 8 26019 1010 1092 4.441075 14.289452 2.562449e+05 2.217566 2017-10-07 2017-12-28 82 days 26.019 4441.075428 14289.4520 9 -22861 1150 1448 9.681759 3.697725 1.368010e+05 0.618073 2018-02-24 2018-12-19 298 days -22.861 9681.758699 3697.7253 10 -20649 1092 1448 14.282307 3.697725 2.185610e+05 0.741097 2017-12-28 2018-12-19 356 days -20.649 14282.307274 3697.7253 11 146957 1448 1677 3.699574 11.790024 1.188948e+06 2.186860 2018-12-19 2019-08-05 229 days 146.957 3699.574163 11790.0240 12 -116762 1677 1749 11.784129 8.003856 4.413922e+05 0.320794 2019-08-05 2019-10-16 72 days -116.762 11784.128988 8003.8560 13 15236 2222 2252 33.174411 48.304707 2.305252e+05 0.456083 2021-01-31 2021-03-02 30 days 15.236 33174.410916 48304.7070 14 210408 1749 2252 8.007858 48.304707 8.478779e+06 5.032163 2019-10-16 2021-03-02 503 days 210.408 8007.857928 48304.7070 15 -163913 2349 2391 33.708044 30.883470 4.629843e+05 0.083795 2021-06-07 2021-07-19 42 days -163.913 33708.043547 30883.4700 16 -11442 2300 2391 55.770238 30.883470 2.847544e+05 0.446237 2021-04-19 2021-07-19 91 days -11.442 55770.237932 30883.4700 17 -161171 2252 2391 48.280555 30.883470 2.803906e+06 0.360333 2021-03-02 2021-07-19 139 days -161.171 48280.554647 30883.4700 18 332295 2391 2489 30.898912 63.031670 1.067755e+07 1.039932 2021-07-19 2021-10-25 98 days 332.295 30898.911735 63031.6700 19 -281616 2489 2584 63.000154 37.768848 7.105540e+06 0.400496 2021-10-25 2022-01-28 95 days -281.616 63000.154165 37768.8480 20 340513 2729 3336 20.013170 51.967000 1.088069e+07 1.596640 2022-06-22 2024-02-19 607 days 340.513 20013.169584 51967.0000 21 601140 2584 3336 37.787732 51.967000 8.523725e+06 0.375235 2022-01-28 2024-02-19 752 days 601.140 37787.732424 51967.0000 22 -698847 3336 3341 51.941017 51.574000 2.564884e+05 0.007066 2024-02-19 2024-02-24 5 days -698.847 51941.016500 51574.0000 23 706948 3341 3363 51.599787 68.209000 1.174185e+07 0.321885 2024-02-24 2024-03-17 22 days 706.948 51599.787000 68209.0000 24 -149634 3443 3541 71.149408 57.382000 2.060072e+06 0.193500 2024-06-05 2024-09-11 98 days -149.634 71149.407500 57382.0000 25 -655632 3363 3541 68.174896 57.382000 7.076168e+06 0.158312 2024-03-17 2024-09-11 178 days -655.632 68174.895500 57382.0000 26 889957 3541 3624 57.410691 95.833000 3.419420e+07 0.669254 2024-09-11 2024-12-03 83 days 889.957 57410.691000 95833.0000

Sheet TS1
A1: Total Strategy 1
A3: Risk Level | B3: Macro Index | C3: NVT Combi | D3: MVRV | E3: NUPL | F3: STH Supply | G3: RHODL ratio | H3: VDD Multiple | I3: M2 YoY Change | J3: Cycle Capital Flows | K3: Fear & Greed
B4: x | D4: x | F4: x | I4: x
A53: Start | B53: 42005
A54: End | B54: 45629
A55: Duration | B55: 3624 days 00:00:00
A56: Exposure Time [%] | B56: 83.889655
A57: Equity Final [$] | B57: 8979372.5
A58: Equity Peak [$] | B58: 9244432.4
A59: Return [%] | B59: 89693.725
A60: Buy & Hold Return [%] | B60: 30344.78
A61: Return (Ann.) [%] | B61: 98.317628
A62: Volatility (Ann.) [%] | B62: 108.467
A63: Sharpe Ratio | B63: 0.90642892
A64: Sortino Ratio | B64: 3.0263918
A65: Calmar Ratio | B65: 1.7737102
A66: Max. Drawdown [%] | B66: -55.43049
A67: Avg. Drawdown [%] | B67: -6.1238853
A68: Max. Drawdown Duration | B68: 484 days 00:00:00
A69: Avg. Drawdown Duration | B69: 23 days 00:00:00
A70: # Trades | B70: 11
A71: Win Rate [%] | B71: 100
A72: Best Trade [%] | B72: 2162.8541
A73: Worst Trade [%] | B73: 50.33301
A74: Avg. Trade [%] | B74: 207.86372
A75: Max. Trade Duration | B75: 910 days 00:00:00
A76: Avg. Trade Duration | B76: 396 days 00:00:00
A77: Profit Factor
A78: Expectancy [%] | B78: 386.43022
A79: SQN | B79: 1.422994
A80: _strategy | B80: Matrix
A81: _equity_curve | B81: Equity DrawdownPct DrawdownDuration time 2015-01-01 1.000000e+04 0.000000 NaT 2015-01-02 1.000000e+04 0.000000 NaT 2015-01-03 1.000000e+04 0.000000 NaT 2015-01-04 1.000000e+04 0.000000 NaT 2015-01-05 1.000000e+04 0.000000 NaT ... ... ... ... 2024-11-29 9.118156e+06 0.013660 NaT 2024-11-30 9.037627e+06 0.022371 NaT 2024-12-01 9.106077e+06 0.014966 NaT 2024-12-02 8.979373e+06 0.028672 NaT 2024-12-03 8.979373e+06 0.028672 11 days [3625 rows x 3 columns]
A82: _trades | B82: Size EntryBar ExitBar EntryPrice ExitPrice PnL ReturnPct EntryTime ExitTime Duration Size_adapted EntryPrice_adapted ExitPrice_adapted 0 24 1051 1096 7.732898 13.464653 1.375621e+02 0.741217 2017-11-17 2018-01-01 45 days 0.024 7732.897516 13464.6530 1 160 992 1096 3.927699 13.464653 1.525913e+03 2.428128 2017-09-19 2018-01-01 104 days 0.160 3927.698868 13464.6530 2 743 931 1096 2.825310 13.464653 7.905032e+03 3.765726 2017-07-20 2018-01-01 165 days 0.743 2825.309949 13464.6530 3 11764 584 1096 0.595030 13.464653 1.513982e+05 21.628541 2016-08-07 2018-01-01 512 days 11.764 595.029666 13464.6530 4 -1420 1105 1416 14.661753 5.501092 1.300814e+04 0.624800 2018-01-10 2018-11-17 311 days -1.420 14661.753456 5501.0923 5 -8892 1096 1416 13.457921 5.501092 7.075212e+04 0.591238 2018-01-01 2018-11-17 320 days -8.892 13457.920674 5501.0923 6 32397 1416 2326 5.503843 47.047965 1.345905e+06 7.548203 2018-11-17 2021-05-15 910 days 32.397 5503.842846 47047.9650 7 -6966 2600 2866 42.174496 20.946803 1.478721e+05 0.503330 2022-02-13 2022-11-06 266 days -6.966 42174.496203 20946.8030 8 -7654 2443 2866 46.425549 20.946803 1.950143e+05 0.548809 2021-09-09 2022-11-06 423 days -7.654 46425.548614 20946.8030 9 -23826 2326 2866 47.024441 20.946803 6.213258e+05 0.554555 2021-05-15 2022-11-06 540 days -23.826 47024.441018 20946.8030 10 85669 2866 3624 20.957276 95.833000 6.414528e+06 3.572779 2022-11-06 2024-12-03 758 days 85.669 20957.276401 95833.0000

Sheet TS2
A1: Total Strategy 2
A3: Risk Level | B3: Macro Index | C3: NVT Combi | D3: MVRV | E3: NUPL | F3: STH Supply | G3: RHODL ratio | H3: VDD Multiple | I3: M2 YoY Change | J3: Cycle Capital Flows | K3: Fear & Greed
A4: x | B4: x | C4: x | G4: x | H4: x
A53: Start | B53: 42005
A54: End | B54: 45629
A55: Duration | B55: 3624 days 00:00:00
A56: Exposure Time [%] | B56: 95.889655
A57: Equity Final [$] | B57: 43770150
A58: Equity Peak [$] | B58: 44894590
A59: Return [%] | B59: 437601.5
A60: Buy & Hold Return [%] | B60: 30344.78
A61: Return (Ann.) [%] | B61: 132.61031
A62: Volatility (Ann.) [%] | B62: 118.44699
A63: Sharpe Ratio | B63: 1.1195751
A64: Sortino Ratio | B64: 4.2492716
A65: Calmar Ratio | B65: 2.6491748
A66: Max. Drawdown [%] | B66: -50.057214
A67: Avg. Drawdown [%] | B67: -5.8685612
A68: Max. Drawdown Duration | B68: 683 days 00:00:00
A69: Avg. Drawdown Duration | B69: 19 days 00:00:00
A70: # Trades | B70: 27
A71: Win Rate [%] | B71: 81.481481
A72: Best Trade [%] | B72: 1033.1914
A73: Worst Trade [%] | B73: -6.6029743
A74: Avg. Trade [%] | B74: 48.209196
A75: Max. Trade Duration | B75: 753 days 00:00:00
A76: Avg. Trade Duration | B76: 129 days 00:00:00
A77: Profit Factor | B77: 165.78846
A78: Expectancy [%] | B78: 85.701822
A79: SQN | B79: 2.8852914
A80: _strategy | B80: Matrix
A81: _equity_curve | B81: Equity DrawdownPct DrawdownDuration time 2015-01-01 1.000000e+04 0.000000 NaT 2015-01-02 1.000000e+04 0.000000 NaT 2015-01-03 1.000000e+04 0.000000 NaT 2015-01-04 1.000000e+04 0.000000 NaT 2015-01-05 1.000000e+04 0.000000 NaT ... ... ... ... 2024-11-29 4.435890e+07 0.011932 NaT 2024-11-30 4.401728e+07 0.019542 NaT 2024-12-01 4.430766e+07 0.013074 NaT 2024-12-02 4.377015e+07 0.025046 NaT 2024-12-03 4.377015e+07 0.025046 11 days [3625 rows x 3 columns]
A82: _trades | B82: Size EntryBar ExitBar EntryPrice ExitPrice PnL ReturnPct EntryTime ExitTime Duration Size_adapted EntryPrice_adapted ExitPrice_adapted 0 30055 149 902 0.232905 2.639261 7.232303e+04 10.331914 2015-05-30 2017-06-21 753 days 30.055 232.905164 2639.2612 1 -21845 902 932 2.637942 2.666140 -6.159860e+02 -0.010689 2017-06-21 2017-07-21 30 days -21.845 2637.941569 2666.1396 2 21441 932 968 2.667473 4.341978 3.590308e+04 0.627750 2017-07-21 2017-08-26 36 days 21.441 2667.472670 4341.9785 3 -18970 968 1001 4.339808 4.187770 2.884152e+03 0.035033 2017-08-26 2017-09-28 33 days -18.970 4339.807511 4187.7700 4 20130 1001 1092 4.189864 14.289452 2.033047e+05 2.410481 2017-09-28 2017-12-28 91 days 20.130 4189.863885 14289.4520 5 -15869 1092 1137 14.282307 8.096728 9.815895e+04 0.433094 2017-12-28 2018-02-11 45 days -15.869 14282.307274 8096.7285 6 36462 1137 1150 8.100777 9.686602 5.782236e+04 0.195762 2018-02-11 2018-02-24 13 days 36.462 8100.776864 9686.6020 7 -34688 1150 1269 9.681759 6.174226 1.216693e+05 0.362283 2018-02-24 2018-06-23 119 days -34.688 9681.758699 6174.2256 8 68154 1269 1677 6.177313 11.790024 3.825287e+05 0.908601 2018-06-23 2019-08-05 408 days 68.154 6177.312713 11790.0240 9 -58450 1677 1734 11.784129 8.314552 2.027968e+05 0.294428 2019-08-05 2019-10-01 57 days -58.450 11784.128988 8314.5520 10 99864 1734 2205 8.318709 39.045520 3.068502e+06 3.693699 2019-10-01 2021-01-14 471 days 99.864 8318.709276 39045.5200 11 -76325 2205 2222 39.025997 33.157832 4.478877e+05 0.150366 2021-01-14 2021-01-31 17 days -76.325 39025.997240 33157.8320 12 99239 2222 2252 33.174411 48.304707 1.501515e+06 0.456083 2021-01-31 2021-03-02 30 days 99.239 33174.410916 48304.7070 13 -89959 2252 2254 48.280555 48.472797 -1.729393e+04 -0.003982 2021-03-02 2021-03-04 2 days -89.959 48280.554647 48472.7970 14 89307 2254 2300 48.497033 55.798137 6.520397e+05 0.150547 2021-03-04 2021-04-19 46 days 89.307 48497.033398 55798.1370 15 -85845 2300 2339 55.770238 35.596720 1.731796e+06 0.361726 2021-04-19 2021-05-28 39 days -85.845 55770.237932 35596.7200 16 168466 2339 2349 35.614518 33.724906 -3.183354e+05 -0.053057 2021-05-28 2021-06-07 10 days 168.466 35614.518360 33724.9060 17 -171384 2349 2371 33.708044 35.933777 -3.814551e+05 -0.066030 2021-06-07 2021-06-29 22 days -171.384 33708.043547 35933.7770 18 153261 2371 2489 35.951744 63.031670 4.150297e+06 0.753230 2021-06-29 2021-10-25 118 days 153.261 35951.743889 63031.6700 19 -133574 2489 2583 63.000154 37.021938 3.470014e+06 0.412352 2021-10-25 2022-01-27 94 days -133.574 63000.154165 37021.9380 20 292766 2583 3336 37.040449 51.967000 4.369987e+06 0.402980 2022-01-27 2024-02-19 753 days 292.766 37040.448969 51967.0000 21 -267673 3336 3337 51.941017 52.287000 -9.261044e+04 -0.006661 2024-02-19 2024-02-20 1 days -267.673 51941.016500 52287.0000 22 264529 3337 3363 52.313143 68.209000 4.204915e+06 0.303860 2024-02-20 2024-03-17 26 days 264.529 52313.143500 68209.0000 23 -246158 3363 3423 68.174896 65.261000 7.172787e+05 0.042741 2024-03-17 2024-05-16 60 days -246.158 68174.895500 65261.0000 24 264710 3423 3443 65.293630 71.185000 1.559504e+06 0.090229 2024-05-16 2024-06-05 20 days 264.710 65293.630500 71185.0000 25 -258267 3443 3541 71.149408 57.382000 3.555667e+06 0.193500 2024-06-05 2024-09-11 98 days -258.267 71149.407500 57382.0000 26 363426 3541 3624 57.410691 95.833000 1.396367e+07 0.669254 2024-09-11 2024-12-03 83 days 363.426 57410.691000 95833.0000

Sheet TS3
A1: Total Strategy 3
A3: Risk Level | B3: Macro Index | C3: NVT Combi | D3: MVRV | E3: NUPL | F3: STH Supply | G3: RHODL ratio | H3: VDD Multiple | I3: M2 YoY Change | J3: Cycle Capital Flows | K3: Fear & Greed
A4: x | B4: x | C4: x | E4: x | G4: x
A53: Start | B53: 42005
A54: End | B54: 45629
A55: Duration | B55: 3624 days 00:00:00
A56: Exposure Time [%] | B56: 99.42069
A57: Equity Final [$] | B57: 99410880
A58: Equity Peak [$] | B58: 102000428
A59: Return [%] | B59: 994008.8
A60: Buy & Hold Return [%] | B60: 30344.78
A61: Return (Ann.) [%] | B61: 152.63891
A62: Volatility (Ann.) [%] | B62: 128.57773
A63: Sharpe Ratio | B63: 1.1871333
A64: Sortino Ratio | B64: 5.0554565
A65: Calmar Ratio | B65: 3.9349439
A66: Max. Drawdown [%] | B66: -38.79062
A67: Avg. Drawdown [%] | B67: -5.3413651
A68: Max. Drawdown Duration | B68: 203 days 00:00:00
A69: Avg. Drawdown Duration | B69: 17 days 00:00:00
A70: # Trades | B70: 33
A71: Win Rate [%] | B71: 78.787879
A72: Best Trade [%] | B72: 471.82108
A73: Worst Trade [%] | B73: -10.688745
A74: Avg. Trade [%] | B74: 43.179887
A75: Max. Trade Duration | B75: 607 days 00:00:00
A76: Avg. Trade Duration | B76: 110 days 00:00:00
A77: Profit Factor | B77: 50.769965
A78: Expectancy [%] | B78: 61.369777
A79: SQN | B79: 2.3607549
A80: _strategy | B80: Matrix
A81: _equity_curve | B81: Equity DrawdownPct DrawdownDuration time 2015-01-01 1.000000e+04 0.000000 NaT 2015-01-02 1.000000e+04 0.000000 NaT 2015-01-03 1.000000e+04 0.000000 NaT 2015-01-04 1.000000e+04 0.000000 NaT 2015-01-05 1.000000e+04 0.000000 NaT ... ... ... ... 2024-11-29 1.007833e+08 0.011932 NaT 2024-11-30 1.000072e+08 0.019542 NaT 2024-12-01 1.006669e+08 0.013074 NaT 2024-12-02 9.944570e+07 0.025046 NaT 2024-12-03 9.941088e+07 0.025388 11 days [3625 rows x 3 columns]
A82: _trades | B82: Size EntryBar ExitBar EntryPrice ExitPrice PnL ReturnPct EntryTime ExitTime Duration Size_adapted EntryPrice_adapted ExitPrice_adapted 0 29944 21 196 0.233764 0.278533 1.340549e+03 0.191512 2015-01-22 2015-07-16 175 days 29.944 233.764204 278.53275 1 -28514 196 239 0.278393 0.232171 1.317994e+03 0.166034 2015-07-16 2015-08-28 43 days -28.514 278.393484 232.17080 2 38146 239 311 0.232287 0.372400 5.344759e+03 0.603190 2015-08-28 2015-11-08 72 days 38.146 232.286885 372.40012 3 -33857 311 432 0.372214 0.411426 -1.327602e+03 -0.105348 2015-11-08 2016-03-08 121 days -33.857 372.213920 411.42596 4 28357 432 539 0.411632 0.627678 6.126422e+03 0.524853 2016-03-08 2016-06-23 107 days 28.357 411.631673 627.67786 5 -25442 539 648 0.627364 0.618085 2.360718e+02 0.014790 2016-06-23 2016-10-10 109 days -25.442 627.364021 618.08520 6 26078 648 798 0.618394 1.193456 1.499645e+04 0.929927 2016-10-10 2017-03-09 150 days 26.078 618.394243 1193.45560 7 -22319 798 819 1.192859 1.037988 3.456570e+03 0.129832 2017-03-09 2017-03-30 21 days -22.319 1192.858872 1037.98770 8 27966 819 896 1.038507 2.409887 3.835201e+04 1.320531 2017-03-30 2017-06-15 77 days 27.966 1038.506694 2409.88670 9 -23203 896 932 2.408682 2.666140 -5.973794e+03 -0.106887 2017-06-15 2017-07-21 36 days -23.203 2408.681757 2666.13960 10 19384 932 963 2.667473 3.992626 2.568677e+04 0.496782 2017-07-21 2017-08-21 31 days 19.384 2667.472670 3992.62600 11 -17463 963 1001 3.990630 4.187770 -3.442661e+03 -0.049401 2017-08-21 2017-09-28 38 days -17.463 3990.629687 4187.77000 12 16057 1001 1081 4.189864 19.250467 2.418281e+05 3.594533 2017-09-28 2017-12-17 80 days 16.057 4189.863885 19250.46700 13 -12294 1081 1137 19.240842 8.096728 1.370057e+05 0.579191 2017-12-17 2018-02-11 56 days -12.294 19240.841767 8096.72850 14 41040 1137 1150 8.100777 9.686602 6.508226e+04 0.195762 2018-02-11 2018-02-24 13 days 41.040 8100.776864 9686.60200 15 -39044 1150 1448 9.681759 3.697725 2.336406e+05 0.618073 2018-02-24 2018-12-19 298 days -39.044 9681.758699 3697.72530 16 146386 1448 1643 3.699574 10.766083 1.034438e+06 1.910087 2018-12-19 2019-07-02 195 days 146.386 3699.574163 10766.08300 17 -117620 1643 1734 10.760700 8.314552 2.877159e+05 0.227322 2019-07-02 2019-10-01 91 days -117.620 10760.699958 8314.55200 18 176358 1734 2247 8.318709 47.568133 6.921950e+06 4.718211 2019-10-01 2021-02-25 513 days 176.358 8318.709276 47568.13300 19 -132769 2247 2254 47.544349 48.472797 -1.232691e+05 -0.019528 2021-02-25 2021-03-04 7 days -132.769 47544.348934 48472.79700 20 128382 2254 2300 48.497033 55.798137 9.373303e+05 0.150547 2021-03-04 2021-04-19 46 days 128.382 48497.033398 55798.13700 21 -123404 2300 2339 55.770238 35.596720 2.489493e+06 0.361726 2021-04-19 2021-05-28 39 days -123.404 55770.237932 35596.72000 22 242174 2339 2349 35.614518 33.724906 -4.576150e+05 -0.053057 2021-05-28 2021-06-07 10 days 242.174 35614.518360 33724.90600 23 -246368 2349 2371 33.708044 35.933777 -5.483495e+05 -0.066030 2021-06-07 2021-06-29 22 days -246.368 33708.043547 35933.77700 24 220316 2371 2443 35.951744 46.448773 2.312663e+06 0.291976 2021-06-29 2021-09-09 72 days 220.316 35951.743889 46448.77300 25 -205482 2443 2584 46.425549 37.768848 1.778796e+06 0.186464 2021-09-09 2022-01-28 141 days -205.482 46425.548614 37768.84800 26 285404 2584 2648 37.787732 45.939900 2.326661e+06 0.215736 2022-01-28 2022-04-02 64 days 285.404 37787.732424 45939.90000 27 -270345 2648 2729 45.916930 20.003168 7.005656e+06 0.564362 2022-04-02 2022-06-22 81 days -270.345 45916.930050 20003.16800 28 865300 2729 3336 20.013170 51.967000 2.764965e+07 1.596640 2022-06-22 2024-02-19 607 days 865.300 20013.169584 51967.00000 29 -706034 3336 3337 51.941017 52.287000 -2.442761e+05 -0.006661 2024-02-19 2024-02-20 1 days -706.034 51941.016500 52287.00000 30 697743 3337 3362 52.313143 66.305000 9.762720e+06 0.267464 2024-02-20 2024-03-16 25 days 697.743 52313.143500 66305.00000 31 -653898 3362 3541 66.271848 57.382000 5.813054e+06 0.134142 2024-03-16 2024-09-11 179 days -653.898 66271.847500 57382.00000 32 825703 3541 3624 57.410691 95.833000 3.172542e+07 0.669254 2024-09-11 2024-12-03 83 days 825.703 57410.691000 95833.00000

Sheet TS4
A1: Total Strategy 4
A3: Risk Level | B3: Macro Index | C3: NVT Combi | D3: MVRV | E3: NUPL | F3: STH Supply | G3: RHODL ratio | H3: VDD Multiple | I3: M2 YoY Change | J3: Cycle Capital Flows | K3: Fear & Greed
A4: x | B4: x | C4: x | E4: x | F4: x | G4: x
A53: Start | B53: 42005 | D53: Start | E53: 42736 | G53: Start | H53: 43101 | J53: Start | K53: 41275
A54: End | B54: 45629 | D54: End | E54: 45629 | G54: End | H54: 45629 | J54: End | K54: 45629
A55: Duration | B55: 3624 days 00:00:00 | D55: Duration | E55: 2893 days 00:00:00 | G55: Duration | H55: 2528 days 00:00:00 | J55: Duration | K55: 4354 days 00:00:00
A56: Exposure Time [%] | B56: 94.593103 | D56: Exposure Time [%] | E56: 75.224603 | G56: Exposure Time [%] | H56: 97.864769 | J56: Exposure Time [%] | K56: 93.226177
A57: Equity Final [$] | B57: 1.4296652e+08 | D57: Equity Final [$] | E57: 1217758.8 | G57: Equity Final [$] | H57: 1225244.9 | J57: Equity Final [$] | K57: 1207580148
A58: Equity Peak [$] | B58: 1.4663929e+08 | D58: Equity Peak [$] | E58: 1249042.2 | G58: Equity Peak [$] | H58: 1256720.1 | J58: Equity Peak [$] | K58: 1239036346
A59: Return [%] | B59: 1429565.2 | D59: Return [%] | E59: 12077.588 | G59: Return [%] | H59: 12152.449 | J59: Return [%] | K59: 12075701
A60: Buy & Hold Return [%] | B60: 30344.78 | D60: Buy & Hold Return [%] | E60: 9509.6554 | G60: Buy & Hold Return [%] | H60: 611.73761 | J60: Buy & Hold Return [%] | K60: 718753.3
A61: Return (Ann.) [%] | B61: 162.05299 | D61: Return (Ann.) [%] | E61: 83.247168 | G61: Return (Ann.) [%] | H61: 100.16331 | J61: Return (Ann.) [%] | K61: 166.63924
A62: Volatility (Ann.) [%] | B62: 162.66957 | D62: Volatility (Ann.) [%] | E62: 92.131552 | G62: Volatility (Ann.) [%] | H62: 119.31467 | J62: Volatility (Ann.) [%] | K62: 152.58025
A63: Sharpe Ratio | B63: 0.99620962 | D63: Sharpe Ratio | E63: 0.9035685 | G63: Sharpe Ratio | H63: 0.83948866 | J63: Sharpe Ratio | K63: 1.0921417
A64: Sortino Ratio | B64: 4.4490227 | D64: Sortino Ratio | E64: 2.6825126 | G64: Sortino Ratio | H64: 2.7512591 | J64: Sortino Ratio | K64: 5.1679105
A65: Calmar Ratio | B65: 2.8034064 | D65: Calmar Ratio | E65: 1.4167012 | G65: Calmar Ratio | H65: 1.6603507 | J65: Calmar Ratio | K65: 3.135208
A66: Max. Drawdown [%] | B66: -57.805741 | D66: Max. Drawdown [%] | E66: -58.761274 | G66: Max. Drawdown [%] | H66: -60.3266 | J66: Max. Drawdown [%] | K66: -53.150937
A67: Avg. Drawdown [%] | B67: -5.9612483 | D67: Avg. Drawdown [%] | E67: -5.2358817 | G67: Avg. Drawdown [%] | H67: -5.7411196 | J67: Avg. Drawdown [%] | K67: -6.0139896
A68: Max. Drawdown Duration | B68: 483 days 00:00:00 | D68: Max. Drawdown Duration | E68: 483 days 00:00:00 | G68: Max. Drawdown Duration | H68: 483 days 00:00:00 | J68: Max. Drawdown Duration | K68: 292 days 00:00:00
A69: Avg. Drawdown Duration | B69: 18 days 00:00:00 | D69: Avg. Drawdown Duration | E69: 18 days 00:00:00 | G69: Avg. Drawdown Duration | H69: 20 days 00:00:00 | J69: Avg. Drawdown Duration | K69: 18 days 00:00:00
A70: # Trades | B70: 24 | D70: # Trades | E70: 14 | G70: # Trades | H70: 17 | J70: # Trades | K70: 24
A71: Win Rate [%] | B71: 91.666667 | D71: Win Rate [%] | E71: 85.714286 | G71: Win Rate [%] | H71: 88.235294 | J71: Win Rate [%] | K71: 95.833333
A72: Best Trade [%] | B72: 5696.5619 | D72: Best Trade [%] | E72: 1171.713 | G72: Best Trade [%] | H72: 754.82028 | J72: Best Trade [%] | K72: 6250.478
A73: Worst Trade [%] | B73: -2.9879527 | D73: Worst Trade [%] | E73: -2.9879527 | G73: Worst Trade [%] | H73: -2.9879527 | J73: Worst Trade [%] | K73: -4.5451172
A74: Avg. Trade [%] | B74: 197.70272 | D74: Avg. Trade [%] | E74: 72.200516 | G74: Avg. Trade [%] | H74: 85.121523 | J74: Avg. Trade [%] | K74: 103.75399
A75: Max. Trade Duration | B75: 878 days 00:00:00 | D75: Max. Trade Duration | E75: 878 days 00:00:00 | G75: Max. Trade Duration | H75: 1049 days 00:00:00 | J75: Max. Trade Duration | K75: 1077 days 00:00:00
A76: Avg. Trade Duration | B76: 278 days 00:00:00 | D76: Avg. Trade Duration | E76: 216 days 00:00:00 | G76: Avg. Trade Duration | H76: 261 days 00:00:00 | J76: Avg. Trade Duration | K76: 245 days 00:00:00
A77: Profit Factor | B77: 3519.1293 | D77: Profit Factor | E77: 469.64163 | G77: Profit Factor | H77: 565.8458 | J77: Profit Factor | K77: 1900.9352
A78: Expectancy [%] | B78: 637.55262 | D78: Expectancy [%] | E78: 145.58892 | G78: Expectancy [%] | H78: 144.50952 | J78: Expectancy [%] | K78: 359.80951
A79: SQN | B79: 2.3067261 | D79: SQN | E79: 2.2525062 | G79: SQN | H79: 2.3421952 | J79: SQN | K79: 2.394498
A80: _strategy | B80: Matrix | D80: _strategy | E80: Matrix | G80: _strategy | H80: Matrix | J80: _strategy | K80: Matrix
A81: _equity_curve | B81: Equity DrawdownPct DrawdownDuration time 2015-01-01 1.000000e+04 0.000000 NaT 2015-01-02 1.000000e+04 0.000000 NaT 2015-01-03 1.000000e+04 0.000000 NaT 2015-01-04 1.000000e+04 0.000000 NaT 2015-01-05 1.000000e+04 0.000000 NaT ... ... ... ... 2024-11-29 1.448896e+08 0.011932 NaT 2024-11-30 1.437737e+08 0.019542 NaT 2024-12-01 1.447222e+08 0.013074 NaT 2024-12-02 1.429665e+08 0.025046 NaT 2024-12-03 1.429665e+08 0.025046 11 days [3625 rows x 3 columns] | D81: _equity_curve | E81: Equity DrawdownPct DrawdownDuration time 2017-01-01 1.000000e+04 0.000000 NaT 2017-01-02 1.000000e+04 0.000000 NaT 2017-01-03 1.000000e+04 0.000000 NaT 2017-01-04 1.000000e+04 0.000000 NaT 2017-01-05 1.000000e+04 0.000000 NaT ... ... ... ... 2024-11-29 1.234139e+06 0.011932 NaT 2024-11-30 1.224634e+06 0.019541 NaT 2024-12-01 1.232713e+06 0.013073 NaT 2024-12-02 1.217759e+06 0.025046 NaT 2024-12-03 1.217759e+06 0.025046 11 days [2894 rows x 3 columns] | G81: _equity_curve | H81: Equity DrawdownPct DrawdownDuration time 2018-01-01 1.000000e+04 0.000000 NaT 2018-01-02 1.000000e+04 0.000000 NaT 2018-01-03 1.000000e+04 0.000000 NaT 2018-01-04 1.000000e+04 0.000000 NaT 2018-01-05 1.000000e+04 0.000000 NaT ... ... ... ... 2024-11-29 1.241725e+06 0.011932 NaT 2024-11-30 1.232163e+06 0.019541 NaT 2024-12-01 1.240291e+06 0.013073 NaT 2024-12-02 1.225245e+06 0.025046 NaT 2024-12-03 1.225245e+06 0.025046 11 days [2529 rows x 3 columns] | J81: _equity_curve | K81: Equity DrawdownPct DrawdownDuration time 2013-01-01 1.000000e+04 0.000000 NaT 2013-01-02 1.000000e+04 0.000000 NaT 2013-01-03 1.000000e+04 0.000000 NaT 2013-01-04 1.000000e+04 0.000000 NaT 2013-01-05 1.000000e+04 0.000000 NaT ... ... ... ... 2024-11-29 1.224252e+09 0.011932 NaT 2024-11-30 1.214824e+09 0.019542 NaT 2024-12-01 1.222838e+09 0.013074 NaT 2024-12-02 1.208003e+09 0.025046 NaT 2024-12-03 1.207580e+09 0.025388 11 days [4355 rows x 3 columns]
A82: _trades | B82: Size EntryBar ExitBar EntryPrice ExitPrice PnL ReturnPct EntryTime ExitTime Duration Size_adapted EntryPrice_adapted ExitPrice_adapted 0 -25144 196 239 0.278393 0.232171 1.162223e+03 0.166034 2015-07-16 2015-08-28 43 days -25.144 278.393484 232.1708 1 4 1001 1096 4.189864 13.464653 3.709916e+01 2.213625 2017-09-28 2018-01-01 95 days 0.004 4189.863885 13464.6530 2 23 932 1096 2.667473 13.464653 2.483351e+02 4.047719 2017-07-21 2018-01-01 164 days 0.023 2667.472670 13464.6530 3 203 819 1096 1.038507 13.464653 2.522508e+03 11.965398 2017-03-30 2018-01-01 277 days 0.203 1038.506694 13464.6530 4 1137 648 1096 0.618394 13.464653 1.460620e+04 20.773574 2016-10-10 2018-01-01 448 days 1.137 618.394243 13464.6530 5 5694 432 1096 0.411632 13.464653 7.432390e+04 31.710440 2016-03-08 2018-01-01 664 days 5.694 411.631673 13464.6530 6 33637 239 1096 0.232287 13.464653 4.450971e+05 56.965619 2015-08-28 2018-01-01 857 days 33.637 232.286885 13464.6530 7 -27430 1150 1448 9.681759 3.697725 1.641420e+05 0.618073 2018-02-24 2018-12-19 298 days -27.430 9681.758699 3697.7253 8 -28503 1096 1448 13.457921 3.697725 2.781948e+05 0.725238 2018-01-01 2018-12-19 352 days -28.503 13457.920674 3697.7253 9 1286 2254 2326 48.497033 47.047965 -1.863502e+03 -0.029880 2021-03-04 2021-05-15 72 days 1.286 48497.033398 47047.9650 10 25000 1734 2326 8.318709 47.047965 9.682314e+05 4.655681 2019-10-01 2021-05-15 592 days 25.000 8318.709276 47047.9650 11 187382 1448 2326 3.699574 47.047965 8.122708e+06 11.717130 2018-12-19 2021-05-15 878 days 187.382 3699.574163 47047.9650 12 -145672 2349 2396 33.708044 34.166914 -6.684458e+04 -0.013613 2021-06-07 2021-07-24 47 days -145.672 33708.043547 34166.9140 13 -150040 2326 2396 47.024441 34.166914 1.929143e+06 0.273422 2021-05-15 2021-07-24 70 days -150.040 47024.441018 34166.9140 14 244535 2396 2443 34.183997 46.448773 2.999167e+06 0.358787 2021-07-24 2021-09-09 47 days 244.535 34183.997457 46448.7730 15 -225277 2443 2585 46.425549 38.088293 1.878192e+06 0.179583 2021-09-09 2022-01-29 142 days -225.277 46425.548614 38088.2930 16 308952 2585 2648 38.107337 45.939900 2.419886e+06 0.205539 2022-01-29 2022-04-02 63 days 308.952 38107.337147 45939.9000 17 -293296 2648 2729 45.916930 20.003168 7.600403e+06 0.564362 2022-04-02 2022-06-22 81 days -293.296 45916.930050 20003.1680 18 32322 3337 3363 52.313143 68.209000 5.137859e+05 0.303860 2024-02-20 2024-03-17 26 days 32.322 52313.143500 68209.0000 19 268940 2866 3363 20.957276 68.209000 1.270788e+07 2.254669 2022-11-06 2024-03-17 497 days 268.940 20957.276401 68209.0000 20 938759 2729 3363 20.013170 68.209000 4.524427e+07 2.408206 2022-06-22 2024-03-17 634 days 938.759 20013.169584 68209.0000 21 -327106 3500 3541 65.325321 57.382000 2.598308e+06 0.121596 2024-08-01 2024-09-11 41 days -327.106 65325.321000 57382.0000 22 -875889 3363 3541 68.174896 57.382000 9.453378e+06 0.158312 2024-03-17 2024-09-11 178 days -875.889 68174.895500 57382.0000 23 1187059 3541 3624 57.410691 95.833000 4.560955e+07 0.669254 2024-09-11 2024-12-03 83 days 1187.059 57410.691000 95833.0000 | D82: _trades | E82: Size EntryBar ExitBar EntryPrice ExitPrice PnL ReturnPct EntryTime ExitTime Duration Size_adapted EntryPrice_adapted ExitPrice_adapted 0 13 1523 1595 48.497033 47.047965 -18.837889 -0.029880 2021-03-04 2021-05-15 72 days 0.013 48497.033398 47047.965 1 199 943 1595 10.534959 47.047965 7266.088224 3.465890 2019-08-02 2021-05-15 652 days 0.199 10534.958847 47047.965 2 1892 717 1595 3.699574 47.047965 82015.155464 11.717130 2018-12-19 2021-05-15 878 days 1.892 3699.574163 47047.965 3 -1434 1618 1665 33.708044 34.166914 -658.020230 -0.013613 2021-06-07 2021-07-24 47 days -1.434 33708.043547 34166.914 4 -1477 1595 1665 47.024441 34.166914 18990.567405 0.273422 2021-05-15 2021-07-24 70 days -1.477 47024.441018 34166.914 5 2408 1665 1712 34.183997 46.448773 29533.579508 0.358787 2021-07-24 2021-09-09 47 days 2.408 34183.997457 46448.773 6 -2218 1712 1854 46.425549 38.088293 18492.032951 0.179583 2021-09-09 2022-01-29 142 days -2.218 46425.548614 38088.293 7 3042 1854 1917 38.107337 45.939900 23826.656200 0.205539 2022-01-29 2022-04-02 63 days 3.042 38107.337147 45939.900 8 -2888 1917 1998 45.916930 20.003168 74838.944800 0.564362 2022-04-02 2022-06-22 81 days -2.888 45916.930050 20003.168 9 1061 2606 2632 52.313143 68.209000 16865.503747 0.303860 2024-02-20 2024-03-17 26 days 1.061 52313.143500 68209.000 10 9243 1998 2632 20.013170 68.209000 445474.060535 2.408206 2022-06-22 2024-03-17 634 days 9.243 20013.169584 68209.000 11 -2786 2769 2810 65.325321 57.382000 22130.092306 0.121596 2024-08-01 2024-09-11 41 days -2.786 65325.321000 57382.000 12 -7460 2632 2810 68.174896 57.382000 80515.000430 0.158312 2024-03-17 2024-09-11 178 days -7.460 68174.895500 57382.000 13 10111 2810 2893 57.410691 95.833000 388487.966299 0.669254 2024-09-11 2024-12-03 83 days 10.111 57410.691000 95833.000 | G82: _trades | H82: Size EntryBar ExitBar EntryPrice ExitPrice PnL ReturnPct EntryTime ExitTime Duration Size_adapted EntryPrice_adapted ExitPrice_adapted 0 -723 54 181 9.681759 6.361402 2400.617676 0.342950 2018-02-24 2018-07-01 127 days -0.723 9681.758699 6361.4023 1 4 1158 1230 48.497033 47.047965 -5.796274 -0.029880 2021-03-04 2021-05-15 72 days 0.004 48497.033398 47047.9650 2 74 578 1230 10.534959 47.047965 2701.962455 3.465890 2019-08-02 2021-05-15 652 days 0.074 10534.958847 47047.9650 3 473 320 1230 5.503843 47.047965 19650.369779 7.548203 2018-11-17 2021-05-15 910 days 0.473 5503.842846 47047.9650 4 1363 181 1230 6.364583 47.047965 55451.449664 6.392152 2018-07-01 2021-05-15 1049 days 1.363 6364.583001 47047.9650 5 -1303 1253 1300 33.708044 34.166914 -597.908200 -0.013613 2021-06-07 2021-07-24 47 days -1.303 33708.043547 34166.9140 6 -1342 1230 1300 47.024441 34.166914 17254.801257 0.273422 2021-05-15 2021-07-24 70 days -1.342 47024.441018 34166.9140 7 2188 1300 1347 34.183997 46.448773 26835.328888 0.358787 2021-07-24 2021-09-09 47 days 2.188 34183.997457 46448.7730 8 -2015 1347 1489 46.425549 38.088293 16799.570061 0.179583 2021-09-09 2022-01-29 142 days -2.015 46425.548614 38088.2930 9 2764 1489 1552 38.107337 45.939900 21649.203727 0.205539 2022-01-29 2022-04-02 63 days 2.764 38107.337147 45939.9000 10 -2624 1552 1633 45.916930 20.003168 67997.711619 0.564362 2022-04-02 2022-06-22 81 days -2.624 45916.930050 20003.1680 11 289 2241 2267 52.313143 68.209000 4593.902529 0.303860 2024-02-20 2024-03-17 26 days 0.289 52313.143500 68209.0000 12 1935 2062 2267 26.053900 68.209000 81570.117649 1.617996 2023-08-25 2024-03-17 205 days 1.935 26053.900440 68209.0000 13 8399 1633 2267 20.013170 68.209000 404796.779664 2.408206 2022-06-22 2024-03-17 634 days 8.399 20013.169584 68209.0000 14 -2803 2404 2445 65.325321 57.382000 22265.128763 0.121596 2024-08-01 2024-09-11 41 days -2.803 65325.321000 57382.0000 15 -7506 2267 2445 68.174896 57.382000 81011.473623 0.158312 2024-03-17 2024-09-11 178 days -7.506 68174.895500 57382.0000 16 10173 2445 2528 57.410691 95.833000 390870.149457 0.669254 2024-09-11 2024-12-03 83 days 10.173 57410.691000 95833.0000 | J82: _trades | K82: Size EntryBar ExitBar EntryPrice ExitPrice PnL ReturnPct EntryTime ExitTime Duration Size_adapted EntryPrice_adapted ExitPrice_adapted 0 34195 295 336 0.204703 1.053621 2.902876e+04 4.147080 2013-10-23 2013-12-03 41 days 34.195 204.702660 1053.62100 1 -22757 685 749 0.387307 0.211920 3.991292e+03 0.452838 2014-11-17 2015-01-20 64 days -22.757 387.307289 211.91986 2 -73857 656 749 0.388490 0.211920 1.304095e+04 0.454504 2014-10-19 2015-01-20 93 days -73.857 388.490158 211.91986 3 -36699 438 749 0.635900 0.211920 1.555967e+04 0.666741 2014-03-15 2015-01-20 311 days -36.699 635.900491 211.91986 4 -25942 336 749 1.053094 0.211920 2.182174e+04 0.798765 2013-12-03 2015-01-20 413 days -25.942 1053.094190 211.91986 5 308498 749 1826 0.212026 13.464653 4.088409e+06 62.504780 2015-01-20 2018-01-01 1077 days 308.498 212.025820 13464.65300 6 -209325 1880 2178 9.681759 3.697725 1.252608e+06 0.618073 2018-02-24 2018-12-19 298 days -209.325 9681.758699 3697.72530 7 -217514 1826 2178 13.457921 3.697725 2.122979e+06 0.725238 2018-01-01 2018-12-19 352 days -217.514 13457.920674 3697.72530 8 1429950 2178 2373 3.699574 10.766083 1.010475e+07 1.910087 2018-12-19 2019-07-02 195 days 1429.950 3699.574163 10766.08300 9 -1148952 2373 2634 10.760700 6.203552 5.235944e+06 0.423499 2019-07-02 2020-03-19 261 days -1148.952 10760.699958 6203.55200 10 144949 2952 2977 33.174411 47.568133 2.086356e+06 0.433880 2021-01-31 2021-02-25 25 days 144.949 33174.410916 47568.13300 11 2582502 2634 2977 6.206654 47.568133 1.068161e+08 6.664055 2020-03-19 2021-02-25 343 days 2582.502 6206.653776 47568.13300 12 -573221 3330 3460 42.174496 21.097104 1.208200e+07 0.499766 2022-02-13 2022-06-23 130 days -573.221 42174.496203 21097.10400 13 -607547 3173 3460 46.425549 21.097104 1.538822e+07 0.545571 2021-09-09 2022-06-23 287 days -607.547 46425.548614 21097.10400 14 -94224 3030 3460 55.770238 21.097104 3.267041e+06 0.621714 2021-04-19 2022-06-23 430 days -94.224 55770.237932 21097.10400 15 -1940512 2977 3460 47.544349 21.097104 5.132120e+07 0.556265 2021-02-25 2022-06-23 483 days -1940.512 47544.348934 21097.10400 16 7092278 3460 3592 21.107653 20.148285 -6.804101e+06 -0.045451 2022-06-23 2022-11-02 132 days 7092.278 21107.652552 20148.28500 17 -7197186 3592 3607 20.138211 16.675180 2.492408e+07 0.171963 2022-11-02 2022-11-17 15 days -7197.186 20138.210858 16675.18000 18 1869800 3888 4066 26.053900 51.967000 4.845231e+07 0.994596 2023-08-25 2024-02-19 178 days 1869.800 26053.900440 51967.00000 19 9733278 3607 4066 16.683518 51.967000 3.434239e+08 2.114871 2022-11-17 2024-02-19 459 days 9733.278 16683.517590 51967.00000 20 -8407588 4066 4071 51.941017 51.574000 3.085724e+06 0.007066 2024-02-19 2024-02-24 5 days -8407.588 51941.016500 51574.00000 21 8505048 4071 4092 51.599787 66.305000 1.250685e+08 0.284986 2024-02-24 2024-03-16 21 days 8505.048 51599.787000 66305.00000 22 -7943141 4092 4271 66.271848 57.382000 7.061331e+07 0.134142 2024-03-16 2024-09-11 179 days -7943.141 66271.847500 57382.00000 23 10030118 4271 4354 57.410691 95.833000 3.853803e+08 0.669254 2024-09-11 2024-12-03 83 days 10030.118 57410.691000 95833.00000

Sheet Risk Level
A1: Risk Level
A53: Start | B53: 42005
A54: End | B54: 45629
A55: Duration | B55: 3624 days 00:00:00
A56: Exposure Time [%] | B56: 84.303448
A57: Equity Final [$] | B57: 2287746.2
A58: Equity Peak [$] | B58: 2500111.2
A59: Return [%] | B59: 22777.462
A60: Buy & Hold Return [%] | B60: 30344.78
A61: Return (Ann.) [%] | B61: 72.809639
A62: Volatility (Ann.) [%] | B62: 91.269725
A63: Sharpe Ratio | B63: 0.79774141
A64: Sortino Ratio | B64: 2.1966336
A65: Calmar Ratio | B65: 0.99186904
A66: Max. Drawdown [%] | B66: -73.406504
A67: Avg. Drawdown [%] | B67: -6.2960982
A68: Max. Drawdown Duration | B68: 612 days
A69: Avg. Drawdown Duration | B69: 23 days
A70: # Trades | B70: 23
A71: Win Rate [%] | B71: 82.608696
A72: Best Trade [%] | B72: 500.91232
A73: Worst Trade [%] | B73: -96.346173
A74: Avg. Trade [%] | B74: 28.630309
A75: Max. Trade Duration | B75: 753 days 00:00:00
A76: Avg. Trade Duration | B76: 160 days 00:00:00
A77: Profit Factor | B77: 13.018794
A78: Expectancy [%] | B78: 62.731503
A79: SQN | B79: 2.8352954
A80: _strategy | B80: Matrix
A81: _equity_curve | B81: Equity DrawdownPct DrawdownDuration time 2015-01-01 1.000000e+04 0.000000 NaT 2015-01-02 1.000000e+04 0.000000 NaT 2015-01-03 1.000000e+04 0.000000 NaT 2015-01-04 1.000000e+04 0.000000 NaT 2015-01-05 1.000000e+04 0.000000 NaT ... ... ... ... 2024-11-29 2.258638e+06 0.096585 NaT 2024-11-30 2.275528e+06 0.089829 NaT 2024-12-01 2.261172e+06 0.095572 NaT 2024-12-02 2.287746e+06 0.084942 NaT 2024-12-03 2.287746e+06 0.084942 11 days [3625 rows x 3 columns]
A82: _trades | B82: Size EntryBar ExitBar EntryPrice ExitPrice PnL ReturnPct EntryTime ExitTime Duration Size_adapted EntryPrice_adapted ExitPrice_adapted 0 -11773 538 647 0.594536 0.617101 -265.663237 -0.037955 2016-06-22 2016-10-09 109 days -11.773 594.535534 617.1010 1 11036 647 797 0.617410 1.152139 5901.278619 0.866086 2016-10-09 2017-03-08 150 days 11.036 617.409551 1152.1394 2 -9504 797 818 1.151563 1.039689 1063.257437 0.097150 2017-03-08 2017-03-29 21 days -9.504 1151.563330 1039.6886 3 11237 818 895 1.040208 2.443825 15772.433618 1.349360 2017-03-29 2017-06-14 77 days 11.237 1040.208444 2443.8245 4 -9305 895 931 2.442603 2.823898 -3547.953811 -0.156102 2017-06-14 2017-07-20 36 days -9.305 2442.602588 2823.8980 5 7166 931 962 2.825310 4.085810 9032.745515 0.446146 2017-07-20 2017-08-20 31 days 7.166 2825.309949 4085.8103 6 -6506 962 1053 4.083767 8.018321 -25598.205755 -0.963462 2017-08-20 2017-11-19 91 days -6.506 4083.767395 8018.3210 7 -553 1085 1136 15.626017 8.530293 3923.935418 0.454097 2017-12-21 2018-02-10 51 days -0.553 15626.017083 8530.2930 8 1335 1136 1149 8.534558 10.159065 2168.716649 0.190345 2018-02-10 2018-02-23 13 days 1.335 8534.558146 10159.0650 9 -1271 1149 1448 10.153985 3.697725 8205.906673 0.635835 2018-02-23 2018-12-19 299 days -1.271 10153.985468 3697.7253 10 5043 1448 1642 3.699574 10.569552 34645.298234 1.856964 2018-12-19 2019-07-01 194 days 5.043 3699.574163 10569.5520 11 -4061 1642 1904 10.564267 6.203552 17708.864525 0.412780 2019-07-01 2020-03-19 262 days -4.061 10564.267224 6203.5520 12 8910 1904 2204 6.206654 37.296547 277010.948626 5.009123 2020-03-19 2021-01-13 300 days 8.910 6206.653776 37296.5470 13 -6685 2204 2395 37.277899 33.439594 25659.067097 0.102965 2021-01-13 2021-07-23 191 days -6.685 37277.898726 33439.5940 14 7985 2395 2488 33.456314 60.865445 218861.912656 0.819251 2021-07-23 2021-10-24 93 days 7.985 33456.313797 60865.4450 15 -6910 2488 2582 60.835012 36.825824 165903.490998 0.394661 2021-10-24 2022-01-26 94 days -6.910 60835.012278 36825.8240 16 7776 2728 3335 20.698809 52.180000 244797.739408 1.520918 2022-06-21 2024-02-18 607 days 7.776 20698.809232 52180.0000 17 14561 2582 3335 36.844237 52.180000 223304.046324 0.416232 2022-01-26 2024-02-18 753 days 14.561 36844.236912 52180.0000 18 -16569 3335 3340 52.153910 50.773000 22880.297790 0.026478 2024-02-18 2024-02-23 5 days -16.569 52153.910000 50773.0000 19 17327 3340 3362 50.798386 66.305000 268683.092115 0.305258 2024-02-23 2024-03-16 22 days 17.327 50798.386500 66305.0000 20 -16119 3362 3540 66.271848 57.624000 139394.653853 0.130491 2024-03-16 2024-09-10 178 days -16.119 66271.847500 57624.0000 21 20221 3540 3617 57.652812 91.932000 693159.460548 0.594580 2024-09-10 2024-11-26 77 days 20.221 57652.812000 91932.0000 22 -17968 3617 3624 91.886034 95.833000 -70919.085088 -0.042955 2024-11-26 2024-12-03 7 days -17.968 91886.034000 95833.0000

Sheet Macro Index
A1: Macro Index
A53: Start | B53: 42005
A54: End | B54: 45629
A55: Duration | B55: 3624 days 00:00:00
A56: Exposure Time [%] | B56: 60.082759
A57: Equity Final [$] | B57: 1476236.1
A58: Equity Peak [$] | B58: 1514657.8
A59: Return [%] | B59: 14662.361
A60: Buy & Hold Return [%] | B60: 30344.78
A61: Return (Ann.) [%] | B61: 65.352799
A62: Volatility (Ann.) [%] | B62: 72.312707
A63: Sharpe Ratio | B63: 0.90375263
A64: Sortino Ratio | B64: 2.4173377
A65: Calmar Ratio | B65: 1.1935069
A66: Max. Drawdown [%] | B66: -54.756951
A67: Avg. Drawdown [%] | B67: -5.5149124
A68: Max. Drawdown Duration | B68: 484 days 00:00:00
A69: Avg. Drawdown Duration | B69: 18 days 00:00:00
A70: # Trades | B70: 19
A71: Win Rate [%] | B71: 89.473684
A72: Best Trade [%] | B72: 1265.5427
A73: Worst Trade [%] | B73: -8.9096029
A74: Avg. Trade [%] | B74: 60.38735
A75: Max. Trade Duration | B75: 878 days 00:00:00
A76: Avg. Trade Duration | B76: 166 days 00:00:00
A77: Profit Factor | B77: 257.18478
A78: Expectancy [%] | B78: 120.80633
A79: SQN | B79: 2.4664014
A80: _strategy | B80: Matrix
A81: _equity_curve | B81: Equity DrawdownPct DrawdownDuration time 2015-01-01 1.000000e+04 0.000000 NaT 2015-01-02 1.000000e+04 0.000000 NaT 2015-01-03 1.000000e+04 0.000000 NaT 2015-01-04 1.000000e+04 0.000000 NaT 2015-01-05 1.000000e+04 0.000000 NaT ... ... ... ... 2024-11-29 1.496600e+06 0.011922 NaT 2024-11-30 1.485084e+06 0.019525 NaT 2024-12-01 1.494872e+06 0.013063 NaT 2024-12-02 1.476753e+06 0.025025 NaT 2024-12-03 1.476236e+06 0.025367 11 days [3625 rows x 3 columns]
A82: _trades | B82: Size EntryBar ExitBar EntryPrice ExitPrice PnL ReturnPct EntryTime ExitTime Duration Size_adapted EntryPrice_adapted ExitPrice_adapted 0 43 2252 2325 48.328859 49.997395 71.747033 0.034525 2021-03-02 2021-05-14 73 days 0.043 48328.859354 49997.395 1 1911 1447 2325 3.661357 49.997395 88548.168496 12.655427 2018-12-18 2021-05-14 878 days 1.911 3661.357064 49997.395 2 -1381 2325 2337 49.972396 39.194860 14883.777634 0.215670 2021-05-14 2021-05-26 12 days -1.381 49972.396303 39194.860 3 2026 2337 2348 39.214457 35.720605 -7078.545023 -0.089096 2021-05-26 2021-06-06 11 days 2.026 39214.457430 35720.605 4 -2086 2348 2370 35.702745 34.376188 2767.197271 0.037156 2021-06-06 2021-06-28 22 days -2.086 35702.744698 34376.188 5 709 2394 2442 32.323113 46.187977 9830.188236 0.428946 2021-07-22 2021-09-08 48 days 0.709 32323.113480 46187.977 6 2222 2370 2442 34.393376 46.187977 26207.603213 0.342932 2021-06-28 2021-09-08 72 days 2.222 34393.376094 46187.977 7 -2202 2442 2584 46.164883 37.768848 18488.069095 0.181871 2021-09-08 2022-01-28 142 days -2.202 46164.883012 37768.848 8 3032 2584 2599 37.787732 42.173460 13297.526010 0.116062 2022-01-28 2022-02-12 15 days 3.032 37787.732424 42173.460 9 -749 2652 2728 43.283286 20.688465 16923.520578 0.522022 2022-04-06 2022-06-21 76 days -0.749 43283.285531 20688.465 10 -2939 2599 2728 42.152373 20.688465 63082.426406 0.509198 2022-02-12 2022-06-21 129 days -2.939 42152.373270 20688.465 11 567 3210 3361 28.521046 68.861000 22872.753693 1.414392 2023-10-16 2024-03-15 151 days 0.567 28521.046397 68861.000 12 3253 2884 3361 16.591815 68.861000 170031.659581 3.150299 2022-11-24 2024-03-15 477 days 3.253 16591.814762 68861.000 13 8692 2728 3361 20.698809 68.861000 418625.762151 2.326810 2022-06-21 2024-03-15 633 days 8.692 20698.809232 68861.000 14 -1452 3491 3540 65.909029 57.624000 12029.862108 0.125704 2024-07-23 2024-09-10 49 days -1.452 65909.029000 57624.000 15 -2751 3437 3540 68.337814 57.624000 29473.702314 0.156777 2024-05-30 2024-09-10 103 days -2.751 68337.814000 57624.000 16 -8833 3361 3540 68.826570 57.624000 98952.296394 0.162765 2024-03-15 2024-09-10 179 days -8.833 68826.569500 57624.000 17 12251 3540 3624 57.652812 95.833000 467745.483188 0.662243 2024-09-10 2024-12-03 84 days 12.251 57652.812000 95833.000 18 -10792 3624 3624 95.785083 95.833000 -517.114868 -0.000500 2024-12-03 2024-12-03 0 days -10.792 95785.083500 95833.000

Sheet NVT Combi
A1: NVT Combi
A53: Start | B53: 42005
A54: End | B54: 45629
A55: Duration | B55: 3624 days 00:00:00
A56: Exposure Time [%] | B56: 74.344828
A57: Equity Final [$] | B57: 1741386.6
A58: Equity Peak [$] | B58: 1903036.3
A59: Return [%] | B59: 17313.866
A60: Buy & Hold Return [%] | B60: 30344.78
A61: Return (Ann.) [%] | B61: 68.126032
A62: Volatility (Ann.) [%] | B62: 90.006043
A63: Sharpe Ratio | B63: 0.75690509
A64: Sortino Ratio | B64: 2.0563923
A65: Calmar Ratio | B65: 0.86236353
A66: Max. Drawdown [%] | B66: -78.999203
A67: Avg. Drawdown [%] | B67: -5.7876492
A68: Max. Drawdown Duration | B68: 1046 days 00:00:00
A69: Avg. Drawdown Duration | B69: 22 days 00:00:00
A70: # Trades | B70: 39
A71: Win Rate [%] | B71: 76.923077
A72: Best Trade [%] | B72: 197.43491
A73: Worst Trade [%] | B73: -21.020894
A74: Avg. Trade [%] | B74: 27.518109
A75: Max. Trade Duration | B75: 489 days 00:00:00
A76: Avg. Trade Duration | B76: 130 days 00:00:00
A77: Profit Factor | B77: 18.789084
A78: Expectancy [%] | B78: 33.983293
A79: SQN | B79: 2.4862077
A80: _strategy | B80: Matrix
A81: _equity_curve | B81: Equity DrawdownPct DrawdownDuration time 2015-01-01 1.000000e+04 0.000000 NaT 2015-01-02 1.000000e+04 0.000000 NaT 2015-01-03 1.000000e+04 0.000000 NaT 2015-01-04 1.000000e+04 0.000000 NaT 2015-01-05 1.000000e+04 0.000000 NaT ... ... ... ... 2024-11-29 1.719230e+06 0.096586 NaT 2024-11-30 1.732086e+06 0.089830 NaT 2024-12-01 1.721158e+06 0.095573 NaT 2024-12-02 1.741387e+06 0.084943 NaT 2024-12-03 1.741387e+06 0.084943 11 days [3625 rows x 3 columns]
